[2024-07-09T20:28:47.134+0000] {local_task_job_runner.py:120} INFO - ::group::Pre task execution logs
[2024-07-09T20:28:47.241+0000] {taskinstance.py:2076} INFO - Dependencies all met for dep_context=non-requeueable deps ti=<TaskInstance: ELT-PROJECT.load.load_customers manual__2024-07-09T20:27:28.353351+00:00 [queued]>
[2024-07-09T20:28:47.296+0000] {taskinstance.py:2076} INFO - Dependencies all met for dep_context=requeueable deps ti=<TaskInstance: ELT-PROJECT.load.load_customers manual__2024-07-09T20:27:28.353351+00:00 [queued]>
[2024-07-09T20:28:47.299+0000] {taskinstance.py:2306} INFO - Starting attempt 1 of 2
[2024-07-09T20:28:47.422+0000] {taskinstance.py:2330} INFO - Executing <Task(_PythonDecoratedOperator): load.load_customers> on 2024-07-09 20:27:28.353351+00:00
[2024-07-09T20:28:47.441+0000] {logging_mixin.py:188} WARNING - /home/airflow/.local/lib/python3.12/site-packages/airflow/task/task_runner/standard_task_runner.py:61 DeprecationWarning: This process (pid=8266) is multi-threaded, use of fork() may lead to deadlocks in the child.
[2024-07-09T20:28:47.469+0000] {standard_task_runner.py:63} INFO - Started process 8332 to run task
[2024-07-09T20:28:47.483+0000] {standard_task_runner.py:90} INFO - Running: ['airflow', 'tasks', 'run', 'ELT-PROJECT', 'load.load_customers', 'manual__2024-07-09T20:27:28.353351+00:00', '--job-id', '138', '--raw', '--subdir', 'DAGS_FOLDER/elt.py', '--cfg-path', '/tmp/tmpupp5_h8f']
[2024-07-09T20:28:47.490+0000] {standard_task_runner.py:91} INFO - Job 138: Subtask load.load_customers
[2024-07-09T20:28:47.587+0000] {logging_mixin.py:188} WARNING - /home/airflow/.local/lib/python3.12/site-packages/airflow/settings.py:195 DeprecationWarning: The sql_alchemy_conn option in [core] has been moved to the sql_alchemy_conn option in [database] - the old setting has been used, but please update your config.
[2024-07-09T20:28:47.730+0000] {task_command.py:426} INFO - Running <TaskInstance: ELT-PROJECT.load.load_customers manual__2024-07-09T20:27:28.353351+00:00 [running]> on host airflow-scheduler
[2024-07-09T20:28:49.315+0000] {taskinstance.py:2648} INFO - Exporting env vars: AIRFLOW_CTX_DAG_OWNER='Data-Ninja' AIRFLOW_CTX_DAG_ID='ELT-PROJECT' AIRFLOW_CTX_TASK_ID='load.load_customers' AIRFLOW_CTX_EXECUTION_DATE='2024-07-09T20:27:28.353351+00:00' AIRFLOW_CTX_TRY_NUMBER='1' AIRFLOW_CTX_DAG_RUN_ID='manual__2024-07-09T20:27:28.353351+00:00'
[2024-07-09T20:28:49.317+0000] {taskinstance.py:430} INFO - ::endgroup::
[2024-07-09T20:28:49.319+0000] {connection.py:399} INFO - Snowflake Connector for Python Version: 3.10.1, Python Version: 3.12.4, Platform: Linux-5.15.133.1-microsoft-standard-WSL2-x86_64-with-glibc2.36
[2024-07-09T20:28:49.321+0000] {connection.py:1249} INFO - THIS CONNECTION IS IN INSECURE MODE. IT MEANS THE CERTIFICATE WILL BE VALIDATED BUT THE CERTIFICATE REVOCATION STATUS WILL NOT BE CHECKED.
[2024-07-09T20:28:49.440+0000] {ssl_wrap_socket.py:100} INFO - THIS CONNECTION IS IN INSECURE MODE. IT MEANS THE CERTIFICATE WILL BE VALIDATED BUT THE CERTIFICATE REVOCATION STATUS WILL NOT BE CHECKED.
[2024-07-09T20:28:49.808+0000] {taskinstance.py:441} INFO - ::group::Post task execution logs
[2024-07-09T20:28:49.809+0000] {taskinstance.py:2905} ERROR - Task failed with exception
Traceback (most recent call last):
  File "/home/airflow/.local/lib/python3.12/site-packages/airflow/models/taskinstance.py", line 465, in _execute_task
    result = _execute_callable(context=context, **execute_callable_kwargs)
             ^^^^^^^^^^^^^^^^^^^^^^^^^^^^^^^^^^^^^^^^^^^^^^^^^^^^^^^^^^^^^
  File "/home/airflow/.local/lib/python3.12/site-packages/airflow/models/taskinstance.py", line 432, in _execute_callable
    return execute_callable(context=context, **execute_callable_kwargs)
           ^^^^^^^^^^^^^^^^^^^^^^^^^^^^^^^^^^^^^^^^^^^^^^^^^^^^^^^^^^^^
  File "/home/airflow/.local/lib/python3.12/site-packages/airflow/models/baseoperator.py", line 401, in wrapper
    return func(self, *args, **kwargs)
           ^^^^^^^^^^^^^^^^^^^^^^^^^^^
  File "/home/airflow/.local/lib/python3.12/site-packages/airflow/decorators/base.py", line 265, in execute
    return_value = super().execute(context)
                   ^^^^^^^^^^^^^^^^^^^^^^^^
  File "/home/airflow/.local/lib/python3.12/site-packages/airflow/models/baseoperator.py", line 401, in wrapper
    return func(self, *args, **kwargs)
           ^^^^^^^^^^^^^^^^^^^^^^^^^^^
  File "/home/airflow/.local/lib/python3.12/site-packages/airflow/operators/python.py", line 235, in execute
    return_value = self.execute_callable()
                   ^^^^^^^^^^^^^^^^^^^^^^^
  File "/home/airflow/.local/lib/python3.12/site-packages/airflow/operators/python.py", line 252, in execute_callable
    return self.python_callable(*self.op_args, **self.op_kwargs)
           ^^^^^^^^^^^^^^^^^^^^^^^^^^^^^^^^^^^^^^^^^^^^^^^^^^^^^
  File "/opt/airflow/dags/elt.py", line 69, in load
    load_func(
  File "/opt/airflow/dags/el_module/loaders.py", line 16, in load_func
    conn = snowflake.connector.connect(
           ^^^^^^^^^^^^^^^^^^^^^^^^^^^^
  File "/home/airflow/.local/lib/python3.12/site-packages/snowflake/connector/__init__.py", line 55, in Connect
    return SnowflakeConnection(**kwargs)
           ^^^^^^^^^^^^^^^^^^^^^^^^^^^^^
  File "/home/airflow/.local/lib/python3.12/site-packages/snowflake/connector/connection.py", line 442, in __init__
    self.connect(**kwargs)
  File "/home/airflow/.local/lib/python3.12/site-packages/snowflake/connector/connection.py", line 745, in connect
    self.__open_connection()
  File "/home/airflow/.local/lib/python3.12/site-packages/snowflake/connector/connection.py", line 1073, in __open_connection
    self.authenticate_with_retry(self.auth_class)
  File "/home/airflow/.local/lib/python3.12/site-packages/snowflake/connector/connection.py", line 1345, in authenticate_with_retry
    self._authenticate(auth_instance)
  File "/home/airflow/.local/lib/python3.12/site-packages/snowflake/connector/connection.py", line 1373, in _authenticate
    auth.authenticate(
  File "/home/airflow/.local/lib/python3.12/site-packages/snowflake/connector/auth/_auth.py", line 401, in authenticate
    Error.errorhandler_wrapper(
  File "/home/airflow/.local/lib/python3.12/site-packages/snowflake/connector/errors.py", line 290, in errorhandler_wrapper
    handed_over = Error.hand_to_other_handler(
                  ^^^^^^^^^^^^^^^^^^^^^^^^^^^^
  File "/home/airflow/.local/lib/python3.12/site-packages/snowflake/connector/errors.py", line 348, in hand_to_other_handler
    connection.errorhandler(connection, cursor, error_class, error_value)
  File "/home/airflow/.local/lib/python3.12/site-packages/snowflake/connector/errors.py", line 221, in default_errorhandler
    raise error_class(
snowflake.connector.errors.DatabaseError: 250001 (08001): None: Failed to connect to DB: sk84886.europe-west2.gcp.snowflakecomputing.com:443. Your free trial has ended and all of your virtual warehouses have been suspended. Add billing information in the Snowflake web UI to continue using the full set of Snowflake features.
[2024-07-09T20:28:49.835+0000] {taskinstance.py:1206} INFO - Marking task as UP_FOR_RETRY. dag_id=ELT-PROJECT, task_id=load.load_customers, run_id=manual__2024-07-09T20:27:28.353351+00:00, execution_date=20240709T202728, start_date=20240709T202847, end_date=20240709T202849
[2024-07-09T20:28:49.855+0000] {standard_task_runner.py:110} ERROR - Failed to execute job 138 for task load.load_customers (250001 (08001): None: Failed to connect to DB: sk84886.europe-west2.gcp.snowflakecomputing.com:443. Your free trial has ended and all of your virtual warehouses have been suspended. Add billing information in the Snowflake web UI to continue using the full set of Snowflake features.; 8332)
[2024-07-09T20:28:49.895+0000] {local_task_job_runner.py:240} INFO - Task exited with return code 1
[2024-07-09T20:28:50.027+0000] {taskinstance.py:3503} INFO - 0 downstream tasks scheduled from follow-on schedule check
[2024-07-09T20:28:50.035+0000] {local_task_job_runner.py:222} INFO - ::endgroup::
